<?xml version="1.0"?>
<robot name="my_robo" >
<property name="M_PI" value="3.14159274"/>
  <link name="base_link">

    <visual>
      <geometry>
        <box size="0.400 0.200 0.100"/>
      </geometry>
    </visual>

    <collision>
      <geometry>
        <box size="0.400 0.200 0.100"/>
      </geometry>
    </collision>

   <inertial>
    <origin xyz="0 0 0"/>
    <mass value="0.500"/>
    <inertia ixx="0.0020833333" ixy="0" ixz="0" iyy="0.0070833333" iyz="0" izz="0.0083333333"/>
   </inertial>
  </link>

  <link name="left_wheel_link">
    <visual>
      <geometry>
        <cylinder radius="0.1" length="0.05"/>
      </geometry>
      <origin xyz="0 0 0" rpy="0 0 0"/>
      <material name="black"/>
    </visual>

    <collision>
      <geometry>
        <cylinder radius="0.1" length="0.05"/>
      </geometry>
    </collision>

   <inertial>
    <origin xyz="0 0 0"/>
    <mass value="0.500"/>
    <inertia ixx="0.0013541667" ixy="0" ixz="0" iyy="0.0013541667" iyz="0" izz="0.0025"/>
   </inertial>

  </link>

  <joint name="left_wheel_joint" type="continuous">
    <parent link="base_link"/>
    <child link="left_wheel_link"/>
    <origin rpy="-1.5707 0 0" xyz="-0.100 0.130 0"/>
    <axis xyz="0 0 1"/>
  </joint>

  <link name="right_wheel_link">
    <visual>
      <geometry>
        <cylinder radius="0.1" length="0.05"/>
      </geometry>
      <origin xyz="0 0 0" rpy="0 0 0"/>
      <material name="black"/>
    </visual>

    <collision>
      <geometry>
        <cylinder radius="0.1" length="0.05"/>
      </geometry>
    </collision>

   <inertial>
    <origin xyz="0 0 0"/>
    <mass value="0.500"/>
    <inertia ixx="0.0013541667" ixy="0" ixz="0" iyy="0.0013541667" iyz="0" izz="0.0025"/>
   </inertial>

  </link>

  <joint name="right_wheel_joint" type="continuous">
    <parent link="base_link"/>
    <child link="right_wheel_link"/>
    <origin rpy="1.5707 0 0" xyz="-0.100 -0.130 0"/>
    <axis xyz="0 0 -1"/>
  </joint>

  <link name="caster_link">
    <visual>
      <geometry>
        <sphere radius="0.05"/>
      </geometry>
      <material name="green">
        <color rgba="0 1 0 1"/>
      </material>
    </visual>

    <collision>
      <geometry>
        <sphere radius="0.05"/>
      </geometry>
    </collision>

   <inertial>
    <origin xyz="0 0 0"/>
    <mass value="0.500"/>
    <inertia ixx="0.00025" ixy="0" ixz="0" iyy="0.00025"  iyz="0" izz="0.00025"/>
   </inertial>

  </link>

  <joint name="caster_joint" type="fixed">
   <parent link="base_link"/>
   <child link="caster_link"/>
   <origin xyz="0.150 0 -0.050"/>
 </joint>

 <link name="base_footprint"/>
  <joint name="base_link_joint" type="fixed">
   <parent link="base_footprint"/>
   <child link="base_link"/>
   <origin xyz="0 0 0.100"/>
 </joint>


  <!-- ===============  Transmission =============== -->
 <transmission name="left_wheel_trans">
      <type>transmission_interface/SimpleTransmission</type>
      <joint name="left_wheel_joint">
  <hardwareInterface>VelocityJointInterface</hardwareInterface>
      </joint>
   <actuator name="left_wheel_motor">
  <hardwareInterface>VelocityJointInterface</hardwareInterface>
  <mechanicalReduction>30</mechanicalReduction>
      </actuator>
 </transmission>
 <transmission name="right_wheel_trans">
      <type>transmission_interface/SimpleTransmission</type>
      <joint name="right_wheel_joint">
  <hardwareInterface>VelocityJointInterface</hardwareInterface>
      </joint>
   <actuator name="right_wheel_motor">
  <hardwareInterface>VelocityJointInterface</hardwareInterface>
  <mechanicalReduction>30</mechanicalReduction>
      </actuator>
 </transmission>

  <!-- =============== Gazebo =============== -->
  <gazebo>
    <plugin name="gazebo_ros_control" filename="libgazebo_ros_control.so">
      <robotNamespace>my_robo</robotNamespace>
    </plugin>
  </gazebo>

 <gazebo reference="base_link">
   <selfCollide>true</selfCollide>
    <mu1 value="0.05" />
    <mu2 value="0.05" />
  </gazebo>

 <gazebo reference="left_wheel_link">
   <selfCollide>true</selfCollide>
    <mu1 value="0.8" />
    <mu2 value="0.8" />
  </gazebo>

 <gazebo reference="right_wheel_link">
   <selfCollide>true</selfCollide>
    <mu1 value="0.8" />
    <mu2 value="0.8" />
  </gazebo>

 <gazebo reference="caster_link">
   <selfCollide>true</selfCollide>
     <!-- This caster is no frictional resistance. -->
    <mu1 value="0.0" />
    <mu2 value="0.0" />
  </gazebo>

  <!-- ========== Sensor ========== -->
  <link name="pico_flexx_link_optical_frame" />
  <link name="pico_flexx_depth_frame"/>
  <link name="pico_flexx_link">
    <visual>
     <geometry>
       <box size="0.007 0.066 0.016"/>
     </geometry>
     <material name="green"/>
    </visual>
    <collision>
     <geometry>
       <box size="0.007 0.066 0.016"/>
     </geometry>
    </collision>
    <inertial>
       <origin xyz="0 0 0" rpy="0 0 0"/>
       <mass value="1"/>
       <inertia
         ixx="1.0" ixy="0.0" ixz="0.0"
         iyy="1.0" iyz="0.0"
         izz="1.0"/>
    </inertial>
  </link>

  <joint name="pico_flexx_base_joint" type="fixed">
    <origin xyz="0.2 0 0.07" rpy="0 0 0"/>
    <parent link="base_link"/>
    <child link="pico_flexx_link_optical_frame"/>
  </joint>

  <joint name="pico_flexx_depth_joint" type="fixed">
    <origin xyz="0 0 0" rpy="${-M_PI/2} 0 ${-M_PI/2}" />
    <parent link="pico_flexx_link_optical_frame" />
    <child link="pico_flexx_depth_frame" />
  </joint>

   <joint name="pico_flexx_joint" type="fixed">
     <origin xyz="0 0 0" rpy="0 0 0"/>
     <parent link="pico_flexx_link_optical_frame"/>
     <child link="pico_flexx_link"/>
   </joint>

   <gazebo reference="pico_flexx_link">
     <sensor type="depth" name="pico_flexx_ir_sensor">
       <always_on>true</always_on>
       <update_rate>0.0</update_rate>
       <camera>
         <horizontal_fov>${57.0*M_PI/180.0}</horizontal_fov>
         <image>
           <format>L8</format>
           <width>640</width>
           <height>480</height>
         </image>
         <clip>
           <near>0.5</near>
           <far>3.0</far>
         </clip>
       </camera>

       <plugin name="pico_flexx_link_controller" filename="libgazebo_ros_openni_kinect.so">
         <alwaysOn>true</alwaysOn>
         <updateRate>1.0</updateRate>
         <cameraName>pico_flexx_link_ir</cameraName>
         <depthImageTopicName>/pico_flexx_link/depth_registered/image_raw</depthImageTopicName>
         <depthImageCameraInfoTopicName>/pico_flexx_link/depth/camera_info</depthImageCameraInfoTopicName>
         <pointCloudTopicName>/pico_flexx_link/points</pointCloudTopicName>
         <frameName>pico_flexx_depth_frame</frameName>
         <pointCloudCutoff>0.5</pointCloudCutoff>
         <distortionK1>0.00000001</distortionK1>
         <distortionK2>0.00000001</distortionK2>
         <distortionK3>0.00000001</distortionK3>
         <distortionT1>0.00000001</distortionT1>
         <distortionT2>0.00000001</distortionT2>
       </plugin>
     </sensor>
     <material value="Gazebo/Blue" />
   </gazebo>
 </robot>
